Workbook

Sheet Master
A1: Site_ID | B1: Site_name | C1: Sorting | D1: Date | E1: Time | F1: latitude | G1: longitude | H1: Air_temp | I1: Cloud (%) | J1: Wind_km.hr | K1: Field_team | L1: Secchi.m | M1: Depth.m | N1: Max_depth.m | O1: DO Calibration% | P1: Sample_depth | Q1: Depth_grouped | R1: Surface_Temp | S1: Surface_DO.sat | T1: Surface_DO.mg.L | U1: Surface_Cond | V1: Surface_Sal.ppt | W1: Surface_pH | X1: Deep_Temp | Y1: Deep_DO.sat | Z1: Deep_DO.mg.L | AA1: Deep_Cond | AB1: Deep_Sal.ppt | AC1: Deep_pH | AD1: TDS.mg.L | AE1: YSI_atm | AF1: Core_length (cm) | AG1: Sediment_depth | AH1: Bottle_Temp_In | AI1: Bottle_temp_out | AJ1: Tows | AK1: Floating_chamberY/N | AL1: Chl_total | AM1: Chla | AN1: NH3.mg.N.L | AO1: SRP.mg.P.L | AP1: Nitrate_Nitrite.ug.N.L | AQ1: TP.mg.P.L | AR1: TN.ug.N.L | AS1: NP_ratio | AT1: DIC.mg.L | AU1: DIC.uM | AV1: DOC.mg.L | AW1: DOC.uM | AX1: pCO2 | AY1: CO2.uM | AZ1: CO2.uM.error | BA1: pCH4 | BB1: CH4.uM | BC1: CH4.uM.error | BD1: pN2O | BE1: N2O.nM | BF1: N2O.nM.error | BG1: d15N_bulk | BH1: d13C_bulk | BI1: mgN_bulk | BJ1: mgC_bulk | BK1: PercentN_bulk | BL1: PercentC_bulk | BM1: sediment_C_N | BN1: d15N_org | BO1: d13C_org | BP1: mgN_org | BQ1: mgC_org | BR1: PercentN_org | BS1: PercentC_org | BT1: d2H | BU1: d18O | BV1: EtoI | BW1: Regime | BX1: Water Source | BY1: Residence_Time | BZ1: General Comments | CA1: Water_class | CB1: Landuse | CC1: Age.years | CD1: NP.ratio | CE1: TA_DIC.umol | CF1: TA_CO2.umol | CG1: b.f.max | CH1: b.f.min
A2: P97 | C2: =A2&D2 -> P9743328 | D2: 43328 | E2: 0.46875 | F2: 52.20959 | G2: -106.07788 | H2: 19.1 | I2: 100 | J2: 14.3 | K2: SE, RR | L2: 1.1 | M2: 1.1 | N2: 1 | O2: 92.2 | P2: 0 | Q2: 0 | R2: 17.9 | S2: 43.8 | T2: 4.13 | U2: 2804 | V2: 1.46 | W2: 8.18 | X2: 17.7 | Y2: 35.2 | Z2: 3.34 | AA2: 2805 | AB2: 1.46 | AC2: 8.16 | AD2: =IF(U2>717.5,(-0.000000000005886729*U2^3)+(0.000001573823009374*U2^2)+( 0.564100864596031*U2)-32.0598990943585, (- 0.00000003351240016*U2^3)+(0.000049948901244919*U2^2)+( 0.500944688449521*U2)-0.00823364899058809) -> 1561.9232 | AE2: 716.1 | AK2: N | AL2: 48.569237 | AM2: 44.579216 | AN2: =VLOOKUP(C2, Triplex!$1:$1048576, 5, FALSE) -> 0.52 | AO2: =VLOOKUP(C2, Triplex!$1:$1048576, 6, FALSE) -> 0.38 | AP2: =VLOOKUP(C2, Triplex!$1:$1048576, 7, FALSE) -> 51.18 | AQ2: =VLOOKUP($C2, TN_TP!$1:$1048576, 6, FALSE) -> 0.43 | AR2: =VLOOKUP($C2, TN_TP!$1:$1048576, 5, FALSE) -> 2920 | AT2: =VLOOKUP($C2, TIC!$1:$1048576, 6, FALSE) -> 67.568 | AV2: =VLOOKUP($C2, TOC!$1:$1048576, 6, FALSE) -> 30.564 | AX2: 2188.804 | AY2: 85.243882 | AZ2: 0.33670897 | BA2: 151.34577 | BB2: 0.22828603 | BC2: 0.00069976415 | BD2: 0.3815643 | BE2: 10.95765 | BF2: 0.067424017 | BZ2: sampled near/ontop of thick macrophyte bed, connected to 98 downstream, surrounded by mainly grasslands, stand of poplar trees nearby | CG2: =VLOOKUP($A2, [1]Buoyancy_max!$B$1:$C$21, 2, FALSE) -> #N/A | CH2: =VLOOKUP(A2, [2]Buoyancy_min!$B$1:$C$21, 2, FALSE) -> #N/A
A3: P26 | C3: =A3&D3 -> P2643329 | D3: 43329 | E3: 0.42361111 | F3: 52.21098 | G3: -106.10072 | H3: 20.6 | I3: 15 | J3: 2.1 | K3: SE, RR | L3: 0.32 | M3: 2.3 | N3: 2 | O3: 92.5 | P3: 0 | Q3: 0 | R3: 18.2 | S3: 40.1 | T3: 3.73 | U3: 3228 | V3: 1.7 | W3: 8.69 | X3: 17.7 | Y3: 8 | Z3: 0.76 | AA3: 3223 | AB3: 1.69 | AC3: 8.63 | AD3: =IF(U3>717.5,(-0.000000000005886729*U3^3)+(0.000001573823009374*U3^2)+( 0.564100864596031*U3)-32.0598990943585, (- 0.00000003351240016*U3^3)+(0.000049948901244919*U3^2)+( 0.500944688449521*U3)-0.00823364899058809) -> 1805.0589 | AE3: 712.8 | AK3: N | AL3: 73.608568 | AM3: 75.456494 | AN3: =VLOOKUP(C3, Triplex!$1:$1048576, 5, FALSE) -> 1.29 | AO3: =VLOOKUP(C3, Triplex!$1:$1048576, 6, FALSE) -> 0.02 | AP3: =VLOOKUP(C3, Triplex!$1:$1048576, 7, FALSE) -> 8.79 | AQ3: =VLOOKUP($C3, TN_TP!$1:$1048576, 6, FALSE) -> 0.09 | AR3: =VLOOKUP($C3, TN_TP!$1:$1048576, 5, FALSE) -> 5810 | AT3: =VLOOKUP($C3, TIC!$1:$1048576, 6, FALSE) -> 71.106 | AV3: =VLOOKUP($C3, TOC!$1:$1048576, 6, FALSE) -> 50.244 | AX3: 630.46271 | AY3: 24.193164 | AZ3: 0.16119471 | BA3: 793.61574 | BB3: 1.182249 | BC3: 0.01283292 | BD3: 0.26960313 | BE3: 7.6229219 | BF3: 0.072750567 | BZ3: lots of birds using the water (seagulls), lots of filamentous algae, smelly water, blue green ring around the water | CG3: =VLOOKUP($A3, [1]Buoyancy_max!$B$1:$C$21, 2, FALSE) -> #N/A | CH3: =VLOOKUP(A3, [2]Buoyancy_min!$B$1:$C$21, 2, FALSE) -> #N/A
A4: P20 | C4: =A4&D4 -> P2043329 | D4: 43329 | E4: 0.48194444 | F4: 52.21152 | G4: -106.09896 | H4: 28.1 | I4: 10 | J4: 1.6 | K4: SE, RR | L4: 0.81 | M4: 0.81 | N4: 0.75 | O4: 96.7 | P4: 0 | Q4: 0 | R4: 18.2 | S4: 112.1 | T4: 11.44 | U4: 2603 | V4: 1.36 | W4: 9.45 | X4: 11.8 | Y4: 80.9 | Z4: 7.79 | AA4: 2586 | AB4: 1.34 | AC4: 9.36 | AD4: =IF(U4>717.5,(-0.000000000005886729*U4^3)+(0.000001573823009374*U4^2)+( 0.564100864596031*U4)-32.0598990943585, (- 0.00000003351240016*U4^3)+(0.000049948901244919*U4^2)+( 0.500944688449521*U4)-0.00823364899058809) -> 1446.8544 | AE4: 712.8 | AK4: N | AL4: -4.2966411 | AM4: 0.48811025 | AN4: =VLOOKUP(C4, Triplex!$1:$1048576, 5, FALSE) -> 0.09 | AO4: =VLOOKUP(C4, Triplex!$1:$1048576, 6, FALSE) -> 0.06 | AP4: =VLOOKUP(C4, Triplex!$1:$1048576, 7, FALSE) -> 3.66 | AQ4: =VLOOKUP($C4, TN_TP!$1:$1048576, 6, FALSE) -> 0.1 | AR4: =VLOOKUP($C4, TN_TP!$1:$1048576, 5, FALSE) -> 2920 | AT4: =VLOOKUP($C4, TIC!$1:$1048576, 6, FALSE) -> 49.2 | AV4: =VLOOKUP($C4, TOC!$1:$1048576, 6, FALSE) -> 36.598 | AX4: 62.457391 | AY4: 2.4005729 | AZ4: 0.079573209 | BA4: 191.42651 | BB4: 0.28578239 | BC4: 0.0027220221 | BD4: 0.22058755 | BE4: 6.2498066 | BF4: 0.056671746 | BZ4: macrophytes, shrimp, located along a fairly busy grid road, orange bottom (maybe cyano-carotenoid pigment) | CG4: =VLOOKUP($A4, [1]Buoyancy_max!$B$1:$C$21, 2, FALSE) -> #N/A | CH4: =VLOOKUP(A4, [2]Buoyancy_min!$B$1:$C$21, 2, FALSE) -> #N/A
A5: P67 | C5: =A5&D5 -> P6743329 | D5: 43329 | E5: 0.45138889 | F5: 52.20877 | G5: -106.0975 | H5: 22.6 | I5: 10 | J5: 1.3 | K5: SE, RR | L5: 0.115 | M5: 2 | N5: 1.75 | O5: 90.5 | P5: 0 | Q5: 0 | R5: 19.2 | S5: 111.3 | T5: 10.07 | U5: 5891 | V5: 3.21 | W5: 8.67 | X5: 17.9 | Y5: 53.2 | Z5: 4.95 | AA5: 5892 | AB5: 3.21 | AC5: 8.61 | AD5: =IF(U5>717.5,(-0.000000000005886729*U5^3)+(0.000001573823009374*U5^2)+( 0.564100864596031*U5)-32.0598990943585, (- 0.00000003351240016*U5^3)+(0.000049948901244919*U5^2)+( 0.500944688449521*U5)-0.00823364899058809) -> 3344.4726 | AE5: 713.3 | AK5: N | AL5: 131.45032 | AM5: 137.15562 | AN5: =VLOOKUP(C5, Triplex!$1:$1048576, 5, FALSE) -> 0.05 | AO5: =VLOOKUP(C5, Triplex!$1:$1048576, 6, FALSE) -> 0.02 | AP5: =VLOOKUP(C5, Triplex!$1:$1048576, 7, FALSE) -> 7.36 | AQ5: =VLOOKUP($C5, TN_TP!$1:$1048576, 6, FALSE) -> 0.11 | AR5: =VLOOKUP($C5, TN_TP!$1:$1048576, 5, FALSE) -> 4480 | AT5: =VLOOKUP($C5, TIC!$1:$1048576, 6, FALSE) -> 88.532 | AV5: =VLOOKUP($C5, TOC!$1:$1048576, 6, FALSE) -> 50.898 | AX5: 644.14163 | AY5: 23.839576 | AZ5: 0.11719601 | BA5: 356.12665 | BB5: 0.5150753 | BC5: 0.004090349 | BD5: 0.2496401 | BE5: 6.7843013 | BF5: 0.022857452 | BZ5: connected to 66, surrounded by grassland, green and murky/turbid water | CG5: =VLOOKUP($A5, [1]Buoyancy_max!$B$1:$C$21, 2, FALSE) -> #N/A | CH5: =VLOOKUP(A5, [2]Buoyancy_min!$B$1:$C$21, 2, FALSE) -> #N/A
A6: P90 | C6: =A6&D6 -> P9043329 | D6: 43329 | E6: 0.38888889 | F6: 52.20428 | G6: -106.08038 | H6: 18.2 | I6: 15 | J6: 1.1 | K6: SE, RR | L6: 0.29 | M6: 4.1 | N6: 4 | O6: 92.7 | P6: 0 | Q6: 0 | R6: 19 | S6: 68.9 | T6: 6.33 | U6: 2851 | V6: 1.49 | W6: 8.56 | X6: 18.7 | Y6: 45.8 | Z6: 4.24 | AA6: 2848 | AB6: 1.49 | AC6: 8.52 | AD6: =IF(U6>717.5,(-0.000000000005886729*U6^3)+(0.000001573823009374*U6^2)+( 0.564100864596031*U6)-32.0598990943585, (- 0.00000003351240016*U6^3)+(0.000049948901244919*U6^2)+( 0.500944688449521*U6)-0.00823364899058809) -> 1588.8476 | AE6: 713.3 | AK6: N | AL6: 69.238972 | AM6: 78.585118 | AN6: =VLOOKUP(C6, Triplex!$1:$1048576, 5, FALSE) -> 0.08 | AO6: =VLOOKUP(C6, Triplex!$1:$1048576, 6, FALSE) -> 0.05 | AP6: =VLOOKUP(C6, Triplex!$1:$1048576, 7, FALSE) -> 2.99 | AQ6: =VLOOKUP($C6, TN_TP!$1:$1048576, 6, FALSE) -> 0.09 | AR6: =VLOOKUP($C6, TN_TP!$1:$1048576, 5, FALSE) -> 2790 | AT6: =VLOOKUP($C6, TIC!$1:$1048576, 6, FALSE) -> 69.077 | AV6: =VLOOKUP($C6, TOC!$1:$1048576, 6, FALSE) -> 34.155 | AX6: 748.09015 | AY6: 28.07679 | AZ6: 0.37722593 | BA6: 442.21065 | BB6: 0.64920382 | BC6: 0.0047301467 | BD6: 0.25268382 | BE6: 6.98136 | BF6: 0.1477625 | BZ6: connected to 98 via small stream, entirely connected to 89, surrounded by mostly trees and some grasslands, water is very green and smelly at shore, lots of dead trees in the water | CG6: =VLOOKUP($A6, [1]Buoyancy_max!$B$1:$C$21, 2, FALSE) -> #N/A | CH6: =VLOOKUP(A6, [2]Buoyancy_min!$B$1:$C$21, 2, FALSE) -> #N/A
A7: P98 | C7: =A7&D7 -> P9843328 | D7: 43328 | E7: 0.44861111 | F7: 52.20856 | G7: -106.07855 | H7: 19.3 | I7: 100 | J7: 9 | K7: SE, RR | L7: 1 | M7: 1 | N7: 0.5 | O7: 95.3 | P7: 0 | Q7: 0 | R7: 17.2 | S7: 43 | T7: 4.1 | U7: 2818 | V7: 1.47 | W7: 8.31 | X7: 17.2 | Y7: 40.9 | Z7: 3.88 | AA7: 2818 | AB7: 1.47 | AC7: 8.31 | AD7: =IF(U7>717.5,(-0.000000000005886729*U7^3)+(0.000001573823009374*U7^2)+( 0.564100864596031*U7)-32.0598990943585, (- 0.00000003351240016*U7^3)+(0.000049948901244919*U7^2)+( 0.500944688449521*U7)-0.00823364899058809) -> 1569.9425 | AE7: 716.2 | AK7: N | AL7: 2.5648534 | AM7: 2.8617203 | AN7: =VLOOKUP(C7, Triplex!$1:$1048576, 5, FALSE) -> 0.25 | AO7: =VLOOKUP(C7, Triplex!$1:$1048576, 6, FALSE) -> 0.38 | AP7: =VLOOKUP(C7, Triplex!$1:$1048576, 7, FALSE) -> 33.88 | AQ7: =VLOOKUP($C7, TN_TP!$1:$1048576, 6, FALSE) -> 0.44 | AR7: =VLOOKUP($C7, TN_TP!$1:$1048576, 5, FALSE) -> 3170 | AT7: =VLOOKUP($C7, TIC!$1:$1048576, 6, FALSE) -> 78.386 | AV7: =VLOOKUP($C7, TOC!$1:$1048576, 6, FALSE) -> 37.124 | AX7: 1545.3645 | AY7: 61.483194 | AZ7: 0.56415197 | BA7: 165.6365 | BB7: 0.25361458 | BC7: 0.0050666519 | BD7: 0.18617832 | BE7: 5.4676896 | BF7: 0.091156938 | BZ7: connected to 9, water drains into small stream with poplar trees on either side, reeds surrounding the pond, grassland mostly surrounding | CG7: =VLOOKUP($A7, [1]Buoyancy_max!$B$1:$C$21, 2, FALSE) -> #N/A | CH7: =VLOOKUP(A7, [2]Buoyancy_min!$B$1:$C$21, 2, FALSE) -> #N/A
A8: P35 | C8: =A8&D8 -> P3543328 | D8: 43328 | E8: 0.41111111 | F8: 52.21161 | G8: -106.10551 | H8: 17.9 | I8: 100 | J8: 6.9 | K8: SE, RR | L8: 0.32 | M8: 0.47 | N8: 0.47 | O8: 96.1 | P8: 0 | Q8: 0 | R8: 16.7 | S8: 38.7 | T8: 3.72 | U8: 3348 | V8: 1.76 | W8: 8.95 | X8: 16.6 | Y8: 29.5 | Z8: 2.85 | AA8: 3351 | AB8: 1.77 | AC8: 8.93 | AD8: =IF(U8>717.5,(-0.000000000005886729*U8^3)+(0.000001573823009374*U8^2)+( 0.564100864596031*U8)-32.0598990943585, (- 0.00000003351240016*U8^3)+(0.000049948901244919*U8^2)+( 0.500944688449521*U8)-0.00823364899058809) -> 1873.97 | AE8: 715.8 | AK8: N | AL8: 9.9595729 | AM8: 11.370566 | AN8: =VLOOKUP(C8, Triplex!$1:$1048576, 5, FALSE) -> 0.53 | AO8: =VLOOKUP(C8, Triplex!$1:$1048576, 6, FALSE) -> 0.64 | AP8: =VLOOKUP(C8, Triplex!$1:$1048576, 7, FALSE) -> 43.73 | AQ8: =VLOOKUP($C8, TN_TP!$1:$1048576, 6, FALSE) -> 0.74 | AR8: =VLOOKUP($C8, TN_TP!$1:$1048576, 5, FALSE) -> 5300 | AT8: =VLOOKUP($C8, TIC!$1:$1048576, 6, FALSE) -> 80.018 | AV8: =VLOOKUP($C8, TOC!$1:$1048576, 6, FALSE) -> 56.078 | AX8: 363.00165 | AY8: 14.636725 | AZ8: 0.76105489 | BA8: 389.43596 | BB8: 0.60130446 | BC8: 0.020062926 | BD8: 0.23471721 | BE8: 6.9887807 | BF8: 0.096569409 | BZ8: pond partially connected, dead trees/shrubary in the connection making a dam, surrounded by grassland | CG8: =VLOOKUP($A8, [1]Buoyancy_max!$B$1:$C$21, 2, FALSE) -> #N/A | CH8: =VLOOKUP(A8, [2]Buoyancy_min!$B$1:$C$21, 2, FALSE) -> #N/A
A9: P37 | C9: =A9&D9 -> P3743328 | D9: 43328 | E9: 0.38402778 | F9: 52.20865 | G9: -106.11012 | H9: 16.1 | I9: 100 | J9: 7.8 | K9: SE, RR | L9: 0.8 | M9: 0.8 | N9: 0.75 | O9: 93.3 | P9: 0 | Q9: 0 | R9: 17.5 | S9: 67.2 | T9: 6.41 | U9: 886 | V9: 0.44 | W9: 8.88 | X9: 17.5 | Y9: 66.6 | Z9: 6.35 | AA9: 884 | AB9: 0.44 | AC9: 8.87 | AD9: =IF(U9>717.5,(-0.000000000005886729*U9^3)+(0.000001573823009374*U9^2)+( 0.564100864596031*U9)-32.0598990943585, (- 0.00000003351240016*U9^3)+(0.000049948901244919*U9^2)+( 0.500944688449521*U9)-0.00823364899058809) -> 468.96482 | AE9: 715.4 | AK9: N | AL9: -2.8039942 | AM9: 1.9816076 | AN9: =VLOOKUP(C9, Triplex!$1:$1048576, 5, FALSE) -> 0.04 | AO9: =VLOOKUP(C9, Triplex!$1:$1048576, 6, FALSE) -> 0.09 | AP9: =VLOOKUP(C9, Triplex!$1:$1048576, 7, FALSE) -> 0.19 | AQ9: =VLOOKUP($C9, TN_TP!$1:$1048576, 6, FALSE) -> 0.13 | AR9: =VLOOKUP($C9, TN_TP!$1:$1048576, 5, FALSE) -> 619.69 | AT9: =VLOOKUP($C9, TIC!$1:$1048576, 6, FALSE) -> 9.989 | AV9: =VLOOKUP($C9, TOC!$1:$1048576, 6, FALSE) -> 7.582 | AX9: 325.99921 | AY9: 12.900721 | AZ9: 0.13584819 | BA9: 794.77622 | BB9: 1.2157216 | BC9: 0.01810751 | BD9: 0.20660371 | BE9: 6.0403919 | BF9: 0.026698019 | BZ9: smokey/hazy out, surrounded by grassland, riparian zone all around, dead trees, macrophytes | CG9: =VLOOKUP($A9, [1]Buoyancy_max!$B$1:$C$21, 2, FALSE) -> #N/A | CH9: =VLOOKUP(A9, [2]Buoyancy_min!$B$1:$C$21, 2, FALSE) -> #N/A
A10: P70 | C10: =A10&D10 -> P7043327 | D10: 43327 | E10: 0.36111111 | F10: 52.2084 | G10: -106.09209 | H10: 20 | I10: 0 | J10: 0 | K10: SE, AK | L10: 0.3 | M10: 0.5 | N10: 0.5 | O10: 89.9 | P10: 0 | Q10: 0 | R10: 17.1 | S10: 17.2 | T10: 1.62 | U10: 5368 | V10: 3.37 | W10: 8.21 | X10: 17 | Y10: 9 | Z10: 0.85 | AA10: 5366 | AB10: 3.47 | AC10: 8.19 | AD10: =IF(U10>717.5,(-0.000000000005886729*U10^3)+(0.000001573823009374*U10^2)+( 0.564100864596031*U10)-32.0598990943585, (- 0.00000003351240016*U10^3)+(0.000049948901244919*U10^2)+( 0.500944688449521*U10)-0.00823364899058809) -> 3040.4734 | AE10: 709.4 | AK10: N | AL10: 148.62798 | AM10: 134.38394 | AN10: =VLOOKUP(C10, Triplex!$1:$1048576, 5, FALSE) -> 0.08 | AO10: =VLOOKUP(C10, Triplex!$1:$1048576, 6, FALSE) -> 0.12 | AP10: =VLOOKUP(C10, Triplex!$1:$1048576, 7, FALSE) -> 6.09 | AQ10: =VLOOKUP($C10, TN_TP!$1:$1048576, 6, FALSE) -> 0.2 | AR10: =VLOOKUP($C10, TN_TP!$1:$1048576, 5, FALSE) -> 5000 | AT10: =VLOOKUP($C10, TIC!$1:$1048576, 6, FALSE) -> 90.433 | AV10: =VLOOKUP($C10, TOC!$1:$1048576, 6, FALSE) -> 45.622 | AX10: 2064.0902 | AY10: 80.854889 | AZ10: 0.89466061 | BA10: 246.95856 | BB10: 0.37082763 | BC10: 0.0027227085 | BD10: 0.097245037 | BE10: 2.8053839 | BF10: 0.0912614 | BZ10: generally round, mostly grass surrounding, in a wetter year would be connected to 71, dam of dead trees, hill slope on one side with shrubs and trees, sampled from .25m, shrimp in pond | CG10: =VLOOKUP($A10, [1]Buoyancy_max!$B$1:$C$21, 2, FALSE) -> #N/A | CH10: =VLOOKUP(A10, [2]Buoyancy_min!$B$1:$C$21, 2, FALSE) -> #N/A
A11: P75 | C11: =A11&D11 -> P7543327 | D11: 43327 | E11: 0.39236111 | F11: 52.205105 | G11: -106.09298 | H11: 21 | I11: 0 | J11: 2.6 | K11: SE, AK | L11: 0.75 | M11: 0.75 | N11: 0.75 | O11: 88.3 | P11: 0 | Q11: 0 | R11: 17.6 | S11: 93.3 | T11: 8.68 | U11: 1368 | V11: 0.81 | W11: 9.28 | X11: 17.5 | Y11: 84.8 | Z11: 8.09 | AA11: 1364 | AB11: 0.81 | AC11: 9.27 | AD11: =IF(U11>717.5,(-0.000000000005886729*U11^3)+(0.000001573823009374*U11^2)+( 0.564100864596031*U11)-32.0598990943585, (- 0.00000003351240016*U11^3)+(0.000049948901244919*U11^2)+( 0.500944688449521*U11)-0.00823364899058809) -> 742.5603 | AE11: 709.4 | AK11: N | AL11: 2.2383234 | AM11: 3.8805997 | AN11: =VLOOKUP(C11, Triplex!$1:$1048576, 5, FALSE) -> 0.11 | AO11: =VLOOKUP(C11, Triplex!$1:$1048576, 6, FALSE) -> 0.36 | AP11: =VLOOKUP(C11, Triplex!$1:$1048576, 7, FALSE) -> 4.05 | AQ11: =VLOOKUP($C11, TN_TP!$1:$1048576, 6, FALSE) -> 0.46 | AR11: =VLOOKUP($C11, TN_TP!$1:$1048576, 5, FALSE) -> 3290 | AT11: =VLOOKUP($C11, TIC!$1:$1048576, 6, FALSE) -> 61.532 | AV11: =VLOOKUP($C11, TOC!$1:$1048576, 6, FALSE) -> 35.093 | AX11: 110.87312 | AY11: 4.3299527 | AZ11: 0.076952481 | BA11: 485.4417 | BB11: 0.73302795 | BC11: 0.032480379 | BD11: 0.19042792 | BE11: 5.4908943 | BF11: 0.053228072 | BZ11: very hazy out, oval shape, 60% dead trees surrounding, 40% reeds, thick mat of algae on the surface at the edges, submerged macrophytes cover bottom, surrounded by grassland | CG11: =VLOOKUP($A11, [1]Buoyancy_max!$B$1:$C$21, 2, FALSE) -> #N/A | CH11: =VLOOKUP(A11, [2]Buoyancy_min!$B$1:$C$21, 2, FALSE) -> #N/A
A12: P66 | C12: =A12&D12 -> P6643327 | D12: 43327 | E12: 0.42291667 | F12: 52.20593 | G12: -106.09621 | H12: 21 | I12: 0 | J12: 0 | K12: SE, AK | L12: 0.21 | M12: 2.7 | N12: 2.5 | O12: 98 | P12: 0 | Q12: 0 | R12: 18.3 | S12: 60 | T12: 5.51 | U12: 4958 | V12: 3.1 | W12: 8.62 | X12: 17.9 | Y12: 455 | Z12: 4.38 | AA12: 4927 | AB12: 3.1 | AC12: 8.66 | AD12: =IF(U12>717.5,(-0.000000000005886729*U12^3)+(0.000001573823009374*U12^2)+( 0.564100864596031*U12)-32.0598990943585, (- 0.00000003351240016*U12^3)+(0.000049948901244919*U12^2)+( 0.500944688449521*U12)-0.00823364899058809) -> 2802.7221 | AE12: 709.5 | AK12: N | AL12: 156.20663 | AM12: 143.50951 | AN12: =VLOOKUP(C12, Triplex!$1:$1048576, 5, FALSE) -> 0.05 | AO12: =VLOOKUP(C12, Triplex!$1:$1048576, 6, FALSE) -> 0.07 | AP12: =VLOOKUP(C12, Triplex!$1:$1048576, 7, FALSE) -> 2.09 | AQ12: =VLOOKUP($C12, TN_TP!$1:$1048576, 6, FALSE) -> 0.16 | AR12: =VLOOKUP($C12, TN_TP!$1:$1048576, 5, FALSE) -> 4830 | AT12: =VLOOKUP($C12, TIC!$1:$1048576, 6, FALSE) -> 96.032 | AV12: =VLOOKUP($C12, TOC!$1:$1048576, 6, FALSE) -> 55.355 | AX12: 694.10289 | AY12: 26.258327 | AZ12: 1.0167788 | BA12: 287.68816 | BB12: 0.42193816 | BC12: 0.046032713 | BD12: 0.27213104 | BE12: 7.5706354 | BF12: 0.14392452 | BZ12: hazy, connected with many other wetlands (65, 67,68, 63, 64, 76, 78…), gravel road on one side, grass on all othersides, 90% reeds and 10% shrubs surrounding | CG12: =VLOOKUP($A12, [1]Buoyancy_max!$B$1:$C$21, 2, FALSE) -> #N/A | CH12: =VLOOKUP(A12, [2]Buoyancy_min!$B$1:$C$21, 2, FALSE) -> #N/A
A13: P88 | C13: =A13&D13 -> P8843327 | D13: 43327 | E13: 0.46597222 | F13: 52.20228 | G13: -106.08401 | H13: 33 | I13: 0 | J13: 3.4 | K13: SE, AK | L13: 0.41 | M13: 0.41 | N13: 0.25 | O13: 95 | P13: 0 | Q13: 0 | R13: 16.2 | S13: 69.2 | T13: 6.77 | U13: 441 | V13: 0.26 | W13: 9.04 | X13: 16 | Y13: 63.1 | Z13: 6.37 | AA13: 440 | AB13: 0.26 | AC13: 9 | AD13: =IF(U13>717.5,(-0.000000000005886729*U13^3)+(0.000001573823009374*U13^2)+( 0.564100864596031*U13)-32.0598990943585, (- 0.00000003351240016*U13^3)+(0.000049948901244919*U13^2)+( 0.500944688449521*U13)-0.00823364899058809) -> 227.74826 | AE13: 709 | AK13: N | AL13: 8.0209972 | AM13: 21.735753 | AN13: =VLOOKUP(C13, Triplex!$1:$1048576, 5, FALSE) -> 0.13 | AO13: =VLOOKUP(C13, Triplex!$1:$1048576, 6, FALSE) -> 1.08 | AP13: =VLOOKUP(C13, Triplex!$1:$1048576, 7, FALSE) -> 5.72 | AQ13: =VLOOKUP($C13, TN_TP!$1:$1048576, 6, FALSE) -> 1.19 | AR13: =VLOOKUP($C13, TN_TP!$1:$1048576, 5, FALSE) -> 2800 | AT13: =VLOOKUP($C13, TIC!$1:$1048576, 6, FALSE) -> 49.3 | AV13: =VLOOKUP($C13, TOC!$1:$1048576, 6, FALSE) -> 30.723 | AX13: 198.44249 | AY13: 8.1068572 | AZ13: 0.80452509 | BA13: 2826.6939 | BB13: 4.4127244 | BC13: 0.92899013 | BD13: 0.13147425 | BE13: 3.9770788 | BF13: 0.34192547 | BZ13: sampled from surface, submerged macrophytes across entire pond reaching surface, 50% dead trees 50% reeds surrounding, fence posts in the water, round, gravel road running beside, hazy out | CG13: =VLOOKUP($A13, [1]Buoyancy_max!$B$1:$C$21, 2, FALSE) -> #N/A | CH13: =VLOOKUP(A13, [2]Buoyancy_min!$B$1:$C$21, 2, FALSE) -> #N/A
... A17: P109 | C17: =A17&D17 -> P10943326 | D17: 43326 | E17: 0.37777778 | F17: 52.20888 | G17: -106.08559 | H17: 15 | I17: 0 | J17: 11 | K17: SE, AK | L17: 0.96 | M17: 1.1 | N17: 0.75 | O17: 100 | P17: 0 | Q17: 0 | R17: 16 | S17: 10.4 | T17: 1.02 | U17: 954 | V17: 0.58 | W17: 7.85 | X17: 16 | Y17: 9.2 | Z17: 0.91 | AA17: 953 | AB17: 0.58 | AC17: 7.75 | AD17: =IF(U17>717.5,(-0.000000000005886729*U17^3)+(0.000001573823009374*U17^2)+( 0.564100864596031*U17)-32.0598990943585, (- 0.00000003351240016*U17^3)+(0.000049948901244919*U17^2)+( 0.500944688449521*U17)-0.00823364899058809) -> 507.51958 | AE17: 713.4 | AK17: N | AL17: 2.7076528 | AM17: 3.717954 | AN17: =VLOOKUP(C17, Triplex!$1:$1048576, 5, FALSE) -> 0.98 | AO17: =VLOOKUP(C17, Triplex!$1:$1048576, 6, FALSE) -> 1.09 | AP17: =VLOOKUP(C17, Triplex!$1:$1048576, 7, FALSE) -> 19.62 | AQ17: =VLOOKUP($C17, TN_TP!$1:$1048576, 6, FALSE) -> 1.19 | AR17: =VLOOKUP($C17, TN_TP!$1:$1048576, 5, FALSE) -> 3200 | AT17: =VLOOKUP($C17, TIC!$1:$1048576, 6, FALSE) -> 73.047 | AV17: =VLOOKUP($C17, TOC!$1:$1048576, 6, FALSE) -> 27.966 | AX17: 5104.9407 | AY17: 210.82823 | AZ17: 3.7783771 | BA17: 1732.0277 | BB17: 2.7270462 | BC17: 0.054111536 | BD17: 0.22178013 | BE17: 6.781465 | BF17: 0.086294705 | BZ17: ducklings swimming in pond, round pond, dead trees in the water about 95% of shoreline, reedy, surrounded by grassland, very clear water (slightly red/brown) | CG17: =VLOOKUP($A17, [1]Buoyancy_max!$B$1:$C$21, 2, FALSE) -> #N/A | CH17: =VLOOKUP(A17, [2]Buoyancy_min!$B$1:$C$21, 2, FALSE) -> #N/A
A18: P118 | C18: =A18&D18 -> P11843326 | D18: 43326 | E18: 0.42083333 | F18: 52.20982 | G18: -106.08421 | H18: 17.4 | I18: 0 | J18: 8.7 | K18: SE, AK | L18: 0.43 | M18: 0.43 | N18: 0.25 | O18: 95.6 | P18: 0 | Q18: 0 | R18: 15.3 | S18: 14.5 | T18: 1.45 | U18: 1217 | V18: 0.76 | W18: 7.8 | X18: 15.2 | Y18: 9.9 | Z18: 0.99 | AA18: 1210 | AB18: 0.76 | AC18: 7.74 | AD18: =IF(U18>717.5,(-0.000000000005886729*U18^3)+(0.000001573823009374*U18^2)+( 0.564100864596031*U18)-32.0598990943585, (- 0.00000003351240016*U18^3)+(0.000049948901244919*U18^2)+( 0.500944688449521*U18)-0.00823364899058809) -> 656.77121 | AE18: 713.1 | AK18: N | AL18: 6.4806952 | AM18: 12.676659 | AN18: =VLOOKUP(C18, Triplex!$1:$1048576, 5, FALSE) -> 0.34 | AO18: =VLOOKUP(C18, Triplex!$1:$1048576, 6, FALSE) -> 4.51 | AP18: =VLOOKUP(C18, Triplex!$1:$1048576, 7, FALSE) -> 7.7 | AQ18: =VLOOKUP($C18, TN_TP!$1:$1048576, 6, FALSE) -> 4.34 | AR18: =VLOOKUP($C18, TN_TP!$1:$1048576, 5, FALSE) -> 3790 | AT18: =VLOOKUP($C18, TIC!$1:$1048576, 6, FALSE) -> 85.06 | AV18: =VLOOKUP($C18, TOC!$1:$1048576, 6, FALSE) -> 45.348 | AX18: 5751.4267 | AY18: 242.47622 | AZ18: 3.3110498 | BA18: 3812.8157 | BB18: 6.0878237 | BC18: 0.1347843 | BD18: 0.087374161 | BE18: 2.7297624 | BZ18: round, shallow, sampled from surface, 50% shore is reeds other 50% is dead trees, floating green plants with small roots "lime green chili flakes", grass in water around edges | CG18: =VLOOKUP($A18, [1]Buoyancy_max!$B$1:$C$21, 2, FALSE) -> #N/A | CH18: =VLOOKUP(A18, [2]Buoyancy_min!$B$1:$C$21, 2, FALSE) -> #N/A
A19: P103 | C19: =A19&D19 -> P10343326 | D19: 43326 | E19: 0.45069444 | F19: 52.20936 | G19: -106.0838 | H19: 20.4 | I19: 2 | J19: 4.8 | K19: SE, AK | L19: 0.28 | M19: 0.36 | N19: 0.25 | O19: 93.3 | P19: 0 | Q19: 0 | R19: 14.4 | S19: 2.9 | T19: 0.29 | U19: 884 | V19: 0.56 | W19: 7.82 | X19: 13.7 | Y19: 1.1 | Z19: 0.11 | AA19: 867 | AB19: 0.55 | AC19: 7.75 | AD19: =IF(U19>717.5,(-0.000000000005886729*U19^3)+(0.000001573823009374*U19^2)+( 0.564100864596031*U19)-32.0598990943585, (- 0.00000003351240016*U19^3)+(0.000049948901244919*U19^2)+( 0.500944688449521*U19)-0.00823364899058809) -> 467.83107 | AE19: 712.5 | AK19: N | AL19: 148.54787 | AM19: 152.58549 | AN19: =VLOOKUP(C19, Triplex!$1:$1048576, 5, FALSE) -> 0.52 | AO19: =VLOOKUP(C19, Triplex!$1:$1048576, 6, FALSE) -> 2.2 | AP19: =VLOOKUP(C19, Triplex!$1:$1048576, 7, FALSE) -> 7.44 | AQ19: =VLOOKUP($C19, TN_TP!$1:$1048576, 6, FALSE) -> 2.23 | AR19: =VLOOKUP($C19, TN_TP!$1:$1048576, 5, FALSE) -> 3720 | AT19: =VLOOKUP($C19, TIC!$1:$1048576, 6, FALSE) -> 76.154 | AV19: =VLOOKUP($C19, TOC!$1:$1048576, 6, FALSE) -> 38.526 | AX19: 5371.101 | AY19: 233.02209 | AZ19: 20.481137 | BA19: 19677.453 | BB19: 32.079861 | BC19: 2.1542961 | BD19: 0.13026974 | BE19: 4.1954541 | BF19: 0.27100817 | BZ19: shallow - sampled from surface, thick layer of plant with small root "floating lime green chili flakes" | CG19: =VLOOKUP($A19, [1]Buoyancy_max!$B$1:$C$21, 2, FALSE) -> #N/A | CH19: =VLOOKUP(A19, [2]Buoyancy_min!$B$1:$C$21, 2, FALSE) -> #N/A
A20: P120 | C20: =A20&D20 -> P12043326 | D20: 43326 | E20: 0.5 | F20: 52.21093 | G20: -106.0825 | H20: 21.3 | I20: 2 | J20: 7.6 | K20: SE, AK | L20: 0.41 | M20: 0.41 | N20: 0.25 | O20: 94.4 | P20: 0 | Q20: 0 | R20: 18.2 | S20: 117 | T20: 10.8 | U20: 822 | V20: 0.47 | W20: 9 | X20: 16.6 | Y20: 114.3 | Z20: 11 | AA20: 796 | AB20: 0.47 | AC20: 9 | AD20: =IF(U20>717.5,(-0.000000000005886729*U20^3)+(0.000001573823009374*U20^2)+( 0.564100864596031*U20)-32.0598990943585, (- 0.00000003351240016*U20^3)+(0.000049948901244919*U20^2)+( 0.500944688449521*U20)-0.00823364899058809) -> 432.69115 | AE20: 711.7 | AK20: N | AL20: 6.5056283 | AM20: 10.26869 | AN20: =VLOOKUP(C20, Triplex!$1:$1048576, 5, FALSE) -> 0.1 | AO20: =VLOOKUP(C20, Triplex!$1:$1048576, 6, FALSE) -> 1.12 | AP20: =VLOOKUP(C20, Triplex!$1:$1048576, 7, FALSE) -> 4.31 | AQ20: =VLOOKUP($C20, TN_TP!$1:$1048576, 6, FALSE) -> 1.21 | AR20: =VLOOKUP($C20, TN_TP!$1:$1048576, 5, FALSE) -> 3110 | AT20: =VLOOKUP($C20, TIC!$1:$1048576, 6, FALSE) -> 53.954 | AV20: =VLOOKUP($C20, TOC!$1:$1048576, 6, FALSE) -> 37.695 | AX20: 214.66302 | AY20: 8.27264 | AZ20: 0.51727462 | BA20: 336.45725 | BB20: 0.50435834 | BC20: 0.013222077 | BD20: 0.14400785 | BE20: 4.0957006 | BF20: 0.12361525 | BZ20: samples from 25cm, saw a couple water mites, circular shape, can see the bottom, submerged macrophytes cover entire pond, 80% treed shoreline | CG20: =VLOOKUP($A20, [1]Buoyancy_max!$B$1:$C$21, 2, FALSE) -> #N/A | CH20: =VLOOKUP(A20, [2]Buoyancy_min!$B$1:$C$21, 2, FALSE) -> #N/A
A21: P124 | C21: =A21&D21 -> P12443326 | D21: 43326 | E21: 0.53611111 | F21: 52.21154 | G21: -106.08027 | H21: 24.4 | I21: 2 | J21: 1 | K21: SE, AK | L21: 1 | M21: 1 | N21: 1 | O21: 101 | P21: 0 | Q21: 0 | R21: 16.4 | S21: 46.3 | T21: 4.57 | U21: 2702 | V21: 1.7 | W21: 8.68 | X21: 15.3 | Y21: 36.2 | Z21: 3.62 | AA21: 2634 | AB21: 1.7 | AC21: 8.72 | AD21: =IF(U21>717.5,(-0.000000000005886729*U21^3)+(0.000001573823009374*U21^2)+( 0.564100864596031*U21)-32.0598990943585, (- 0.00000003351240016*U21^3)+(0.000049948901244919*U21^2)+( 0.500944688449521*U21)-0.00823364899058809) -> 1503.5147 | AE21: 711.5 | AK21: N | AL21: -4.2464993 | AM21: 1.6115893 | AN21: =VLOOKUP(C21, Triplex!$1:$1048576, 5, FALSE) -> 0.12 | AO21: =VLOOKUP(C21, Triplex!$1:$1048576, 6, FALSE) -> 0.05 | AP21: =VLOOKUP(C21, Triplex!$1:$1048576, 7, FALSE) -> 5.69 | AQ21: =VLOOKUP($C21, TN_TP!$1:$1048576, 6, FALSE) -> 0.09 | AR21: =VLOOKUP($C21, TN_TP!$1:$1048576, 5, FALSE) -> 3270 | AT21: =VLOOKUP($C21, TIC!$1:$1048576, 6, FALSE) -> 37.113 | AV21: =VLOOKUP($C21, TOC!$1:$1048576, 6, FALSE) -> 37.339 | AX21: 254.04034 | AY21: 10.279268 | AZ21: 0.22379187 | BA21: 234.50359 | BB21: 0.36240493 | BC21: 0.003782211 | BD21: 0.20852411 | BE21: 6.2341024 | BF21: 0.018494668 | BZ21: large and round, grass and reeds on all sides, few dead trees, grassland surrounding | CG21: =VLOOKUP($A21, [1]Buoyancy_max!$B$1:$C$21, 2, FALSE) -> #N/A | CH21: =VLOOKUP(A21, [2]Buoyancy_min!$B$1:$C$21, 2, FALSE) -> #N/A

Sheet Triplex
A1: Sorting | B1: Site_ID | C1: Date | D1: Sample | E1: Ammonia (mg NH3-N/L) | F1: SRP (mg P/L) | G1: Nitrate/Nitrite (ug N/L)
A2: =B2&C2 -> 2343321 | B2: 23 | C2: 43321 | D2: 23-AUG9 | E2: 0.13 | F2: 0.02 | G2: 5.87
A3: =B3&C3 -> 2343237 | B3: 23 | C3: 43237 | D3: 23-MAY17 | E3: 0.04 | F3: 0.00913 | G3: 5.94
A4: =B4&C4 -> 2343370 | B4: 23 | C4: 43370 | D4: 23-SEPT27 | E4: 0.05 | F4: 0.01 | G4: 9.26
A5: =B5&C5 -> 2343262 | B5: 23 | C5: 43262 | D5: 23-JUN11 | E5: 0.01 | F5: 0.02 | G5: 38.27
A6: =B6&C6 -> 2343293 | B6: 23 | C6: 43293 | D6: 23-JUL12 | E6: 0.14 | F6: 0.01 | G6: 11.15
A7: =B7&C7 -> 6843216 | B7: 68 | C7: 43216 | D7: 68-APR26 | E7: 3.45 | F7: 0.00721 | G7: 3206.76
A8: =B8&C8 -> 6843238 | B8: 68 | C8: 43238 | D8: 68-MAY18 | E8: 0.58 | F8: 0.04 | G8: 104.64
A9: =B9&C9 -> 6843294 | B9: 68 | C9: 43294 | D9: 68-JUL13 | E9: 0.03 | F9: 0.91 | G9: 131.11
A10: =B10&C10 -> 14A43371 | B10: 14A | C10: 43371 | D10: 14A-SEP28 | E10: 0.65 | F10: 1.82 | G10: 82.43
A11: =B11&C11 -> 14A43238 | B11: 14A | C11: 43238 | D11: 14A-MAY18 | E11: 0.24 | F11: 1.77 | G11: 9.02
A12: =B12&C12 -> 14A43294 | B12: 14A | C12: 43294 | D12: 14A-JUL13 | E12: 0.08 | F12: 2.89 | G12: 2967.72
A13: =B13&C13 -> 14A43216 | B13: 14A | C13: 43216 | D13: 14A-APR26 | E13: 2.58 | F13: 1.73 | G13: 562.05
A14: =B14&C14 -> 14A0 Hr | B14: 14A | C14: 0 Hr | D14: 14A-0H-JUN26 | E14: 2.24 | F14: 3.48 | G14: 2912.72
A15: =B15&C15 -> 14A12 Hr | B15: 14A | C15: 12 Hr | D15: 14A-12H-JUN26 | E15: 1.08 | F15: 3.72 | G15: 4080
A16: =B16&C16 -> 14A24 Hr | B16: 14A | C16: 24 Hr | D16: 14A-24H-JUN26 | E16: 2.52 | F16: 3.76 | G16: 2953
A17: =B17&C17 -> 14B43371 | B17: 14B | C17: 43371 | D17: 14B-SEP28 | E17: 0.07 | F17: 0.16 | G17: 18.25
A18: =B18&C18 -> 14B43238 | B18: 14B | C18: 43238 | D18: 14B-MAY18 | E18: 0.07 | F18: 0.28 | G18: 10.13
A19: =B19&C19 -> 14B43216 | B19: 14B | C19: 43216 | D19: 14B-APR26 | E19: 0.36 | F19: 0.62 | G19: 468.29
A20: =B20&C20 -> 14B43294 | B20: 14B | C20: 43294 | D20: 14B-JUL13 | E20: 0.03 | F20: 0.14 | G20: 236.96
A21: =B21&C21 -> 230 Hr | B21: 23 | C21: 0 Hr | D21: 23-0H-JUL31 | E21: 0.12 | F21: 0.00897 | G21: 11.49
A22: =B22&C22 -> 2312 Hr | B22: 23 | C22: 12 Hr | D22: 23-12H-JUL31 | E22: 0.08 | F22: 0.00112 | G22: 6.84
A23: =B23&C23 -> 2324 Hr | B23: 23 | C23: 24 Hr | D23: 23-24H-AUG1 | E23: 0.12 | F23: 0.001 | G23: 6.42
A24: =B24&C24 -> 32A43370 | B24: 32A | C24: 43370 | D24: 32A-SEP27 | E24: 2.01 | F24: 0.72 | G24: 17.3
A25: =B25&C25 -> 32A43221 | B25: 32A | C25: 43221 | D25: 32A-MAY1 | E25: 0.73 | F25: 0.62 | G25: 525.43
A26: =B26&C26 -> 32A43293 | B26: 32A | C26: 43293 | D26: 32A-JUL12 | E26: 0.11 | F26: 0.51 | G26: 16.68
A27: =B27&C27 -> 32A43243 | B27: 32A | C27: 43243 | D27: 32A-MAY23 | E27: 0.04 | F27: 0.39 | G27: 13.14
A28: =B28&C28 -> 32B43370 | B28: 32B | C28: 43370 | D28: 32B-SEP27 | E28: 0.12 | F28: 0.52 | G28: 6.4
A29: =B29&C29 -> 32B43221 | B29: 32B | C29: 43221 | D29: 32B-MAY1 | E29: 0.13 | F29: 1.22 | G29: 384.09
A30: =B30&C30 -> 32B43243 | B30: 32B | C30: 43243 | D30: 32B-MAY23 | E30: 0.12 | F30: 1.11 | G30: 73.78
A31: =B31&C31 -> 32B43293 | B31: 32B | C31: 43293 | D31: 32B-JUL12 | E31: 0.07 | F31: 0.54 | G31: 7.36
A32: =B32&C32 -> 32C43237 | B32: 32C | C32: 43237 | D32: 32C-MAY17 | E32: 0.06 | F32: 0.25 | G32: 4.16
A33: =B33&C33 -> 32C43221 | B33: 32C | C33: 43221 | D33: 32C-MAY1 | E33: 0.12 | F33: 0.32 | G33: 248.76
A34: =B34&C34 -> 32C43370 | B34: 32C | C34: 43370 | D34: 32C-SEP27 | E34: 0.08 | F34: 0.06 | G34: 12.58
A35: =B35&C35 -> 32C43293 | B35: 32C | C35: 43293 | D35: 32C-JUL12 | E35: 0.06 | F35: 0.16 | G35: 196.63
... A45: =B45&C45 -> 4C43214 | B45: 4C | C45: 43214 | D45: 4C-APR24 | E45: 0.03 | F45: 0.00873 | G45: 384.37
A46: =B46&C46 -> 4C0 Hr | B46: 4C | C46: 0 Hr | D46: 4C-0H-JUL25 | E46: 0.04 | F46: 0.00167 | G46: 6.07
A47: =B47&C47 -> 4C12 Hr | B47: 4C | C47: 12 Hr | D47: 4C-12H-JUL25 | E47: 0.06 | F47: 0.00155 | G47: 5.05
A48: =B48&C48 -> 4C24 Hr | B48: 4C | C48: 24 Hr | D48: 4C-24H-JUL26 | E48: 0.05 | F48: 0.00555 | G48: 3.66
A49: =B49&C49 -> 4D43236 | B49: 4D | C49: 43236 | D49: 4D-MAY16 | E49: 0.19 | F49: 0.02 | G49: 8.93
...

Sheet TN_TP
A1: Sorting | B1: Site_ID | C1: Date | D1: Sample | E1: TN (ug N/L) | F1: TP (mg P/L)
A2: =B2&C2 -> 2343321 | B2: 23 | C2: 43321 | D2: 23-AUG9 | E2: 1590 | F2: 0.04
A3: =B3&C3 -> 2343237 | B3: 23 | C3: 43237 | D3: 23-MAY17 | E3: 930.53 | F3: 0.04
A4: =B4&C4 -> 2343370 | B4: 23 | C4: 43370 | D4: 23-SEP27 | E4: 1660 | F4: 0.05
A5: =B5&C5 -> 2343262 | B5: 23 | C5: 43262 | D5: 23-JUN11 | E5: 942.01 | F5: 0.04
A6: =B6&C6 -> 2343293 | B6: 23 | C6: 43293 | D6: 23-JUL11 | E6: 1410 | F6: 0.04
A7: =B7&C7 -> 6843216 | B7: 68 | C7: 43216 | D7: 68-APR26 | E7: 9950 | F7: 0.05
A8: =B8&C8 -> 6843238 | B8: 68 | C8: 43238 | D8: 68-MAY18 | E8: 2520 | F8: 0.08
A9: =B9&C9 -> 6843294 | B9: 68 | C9: 43294 | D9: 68-JUL13 | E9: 2480 | F9: 0.96
A10: =B10&C10 -> 14A43371 | B10: 14A | C10: 43371 | D10: 14A-SEP28 | E10: 5820 | F10: 1.83
A11: =B11&C11 -> 14A43238 | B11: 14A | C11: 43238 | D11: 14A-MAY18 | E11: 3550 | F11: 1.9
A12: =B12&C12 -> 14A43294 | B12: 14A | C12: 43294 | D12: 14A-JUL13 | E12: 9300 | F12: 3.8
A13: =B13&C13 -> 14A43216 | B13: 14A | C13: 43216 | D13: 14A-APR26 | E13: 5570 | F13: 1.81
A14: =B14&C14 -> 14A0 Hr | B14: 14A | C14: 0 Hr | D14: 14A-0H-JUN26 | E14: 11250 | F14: 4.8
A15: =B15&C15 -> 14A12 Hr | B15: 14A | C15: 12 Hr | D15: 14A-12H-JUN26 | E15: 11500 | F15: 4.85
A16: =B16&C16 -> 14A24 Hr | B16: 14A | C16: 24 Hr | D16: 14A-24H-JUN26 | E16: 12150 | F16: 4.95
A17: =B17&C17 -> 14B43371 | B17: 14B | C17: 43371 | D17: 14B-SEP28 | E17: 2430 | F17: 0.21
A18: =B18&C18 -> 14B43238 | B18: 14B | C18: 43238 | D18: 14B-MAY18 | E18: 1990 | F18: 0.33
A19: =B19&C19 -> 14B43216 | B19: 14B | C19: 43216 | D19: 14B-APR26 | E19: 13450 | F19: 3.35
A20: =B20&C20 -> 14B43294 | B20: 14B | C20: 43294 | D20: 14B-JUL13 | E20: 2530 | F20: 0.18
A21: =B21&C21 -> 230 Hr | B21: 23 | C21: 0 Hr | D21: 23-0H-JUL31 | E21: 1510 | F21: 0.04
A22: =B22&C22 -> 2312 Hr | B22: 23 | C22: 12 Hr | D22: 23-12H-JUL31 | E22: 1610 | F22: 0.03
A23: =B23&C23 -> 2324 Hr | B23: 23 | C23: 24 Hr | D23: 23-24H-AUG1 | E23: 1500 | F23: 0.03
A24: =B24&C24 -> 32A43370 | B24: 32A | C24: 43370 | D24: 32A-SEP27 | E24: 5640 | F24: 0.8
A25: =B25&C25 -> 32A43221 | B25: 32A | C25: 43221 | D25: 32A-MAY1 | E25: 3550 | F25: 0.7
A26: =B26&C26 -> 32A43293 | B26: 32A | C26: 43293 | D26: 32A-JUL12 | E26: 2380 | F26: 0.57
A27: =B27&C27 -> 32A43243 | B27: 32A | C27: 43243 | D27: 32A-MAY23 | E27: 2230 | F27: 0.47
A28: =B28&C28 -> 32B43370 | B28: 32B | C28: 43370 | D28: 32B-SEP27 | E28: 2540 | F28: 0.58
A29: =B29&C29 -> 32B43221 | B29: 32B | C29: 43221 | D29: 32B-MAY1 | E29: 2410 | F29: 1.31
A30: =B30&C30 -> 32B43243 | B30: 32B | C30: 43243 | D30: 32B-MAY23 | E30: 2180 | F30: 1.16
A31: =B31&C31 -> 32B43293 | B31: 32B | C31: 43293 | D31: 32B-JUL12 | E31: 2080 | F31: 0.58
A32: =B32&C32 -> 32C43237 | B32: 32C | C32: 43237 | D32: 32C-MAY17 | E32: 1790 | F32: 0.33
A33: =B33&C33 -> 32C43221 | B33: 32C | C33: 43221 | D33: 32C-MAY1 | E33: 1790 | F33: 0.36
A34: =B34&C34 -> 32C43370 | B34: 32C | C34: 43370 | D34: 32C-SEP27 | E34: 2830 | F34: 0.13
A35: =B35&C35 -> 32C43293 | B35: 32C | C35: 43293 | D35: 32C-JUL12 | E35: 2390 | F35: 0.21
... A45: =B45&C45 -> 4C43214 | B45: 4C | C45: 43214 | D45: 4C-APR24 | E45: 1670 | F45: 0.02
A46: =B46&C46 -> 4C0 Hr | B46: 4C | C46: 0 Hr | D46: 4C-0H-JUL25 | E46: 1400 | F46: 0.03
A47: =B47&C47 -> 4C12 Hr | B47: 4C | C47: 12 Hr | D47: 4C-12H-JUL25 | E47: 1440 | F47: 0.03
A48: =B48&C48 -> 4C24 Hr | B48: 4C | C48: 24 Hr | D48: 4C-24H-JUL26 | E48: 1390 | F48: 0.03
A49: =B49&C49 -> 4D43236 | B49: 4D | C49: 43236 | D49: 4D-MAY16 | E49: 1420 | F49: 0.04
...

Sheet TIC
A1: Sorting | B1: Site_ID | C1: Date | D1: Sample | E1: TOC/TIC | F1: PPM
A2: =B2&C2 -> 2343370 | B2: 23 | C2: 43370 | D2: Dugout2018_23-SEPT27 | E2: TIC | F2: 24.57
A3: =B3&C3 -> 2343321 | B3: 23 | C3: 43321 | D3: Dugout2018_23-AUG9 | E3: TIC | F3: 13.659
A4: =B4&C4 -> 2343237 | B4: 23 | C4: 43237 | D4: Dugout2018_23-MAY17 | E4: TIC | F4: 21.191
A5: =B5&C5 -> 2343293 | B5: 23 | C5: 43293 | D5: Dugout2018_23-JULY12 | E5: TIC | F5: 15.851
A6: =B6&C6 -> 2343262 | B6: 23 | C6: 43262 | D6: Dugout2018_23-JUNE11 | E6: TIC | F6: 24.918
A7: =B7&C7 -> 6843294 | B7: 68 | C7: 43294 | D7: Dugout2018_68-JULY13 | E7: TIC | F7: 30.243
A8: =B8&C8 -> 6843238 | B8: 68 | C8: 43238 | D8: Dugout2018_68-MAY18 | E8: TIC | F8: 34.085
A9: =B9&C9 -> 6843216 | B9: 68 | C9: 43216 | D9: Dugout2018_68-APR26 | E9: TIC | F9: 31.269
A10: =B10&C10 -> 14A43371 | B10: 14A | C10: 43371 | D10: Dugout2018_14A-SEPT28 | E10: TIC | F10: 99.942
A11: =B11&C11 -> 14A43238 | B11: 14A | C11: 43238 | D11: Dugout2018_14A-MAY18 | E11: TIC | F11: 56.928
A12: =B12&C12 -> 14A43294 | B12: 14A | C12: 43294 | D12: Dugout2018_14A-JULY13 | E12: TIC | F12: 96.088
A13: =B13&C13 -> 14A43216 | B13: 14A | C13: 43216 | D13: Dugout2018_14A-APR26 | E13: TIC | F13: 28.435
A14: =B14&C14 -> 14A0 Hr | B14: 14A | C14: 0 Hr | D14: Dugout2018_14A-0H-JUNE26 | E14: TIC | F14: 98.145
A15: =B15&C15 -> 14A12 Hr | B15: 14A | C15: 12 Hr | D15: Dugout2018_14A-12H-JUNE26 | E15: TIC | F15: 95.094
A16: =B16&C16 -> 14A24 Hr | B16: 14A | C16: 24 Hr | D16: Dugout2018_14A-24H-JUNE26 | E16: TIC | F16: 106.237
A17: =B17&C17 -> 14B43371 | B17: 14B | C17: 43371 | D17: Dugout2018_14B-SEPT28 | E17: TIC | F17: 39.222
A18: =B18&C18 -> 14B43238 | B18: 14B | C18: 43238 | D18: Dugout2018_14B-MAY18 | E18: TIC | F18: 41.531
A19: =B19&C19 -> 14B43294 | B19: 14B | C19: 43294 | D19: Dugout2018_14B-JULY13 | E19: TIC | F19: 41.572
A20: =B20&C20 -> 14B43216 | B20: 14B | C20: 43216 | D20: Dugout2018_14B-APR26 | E20: TIC | F20: 30.245
A21: =B21&C21 -> 230 Hr | B21: 23 | C21: 0 Hr | D21: Dugout2018_23-0h-JULY31 | E21: TIC | F21: 15.234
A22: =B22&C22 -> 2312 Hr | B22: 23 | C22: 12 Hr | D22: Dugout2018_23-12h-JULY31 | E22: TIC | F22: 17.543
A23: =B23&C23 -> 2324 Hr | B23: 23 | C23: 24 Hr | D23: Dugout2018_23-24h-AUG1 | E23: TIC | F23: 16.061
A24: =B24&C24 -> 32A43370 | B24: 32A | C24: 43370 | D24: Dugout2018_32A-SEPT27 | E24: TIC | F24: 77.767
A25: =B25&C25 -> 32A43221 | B25: 32A | C25: 43221 | D25: Dugout2018_32A-MAY1 | E25: TIC | F25: 41.663
A26: =B26&C26 -> 32A43293 | B26: 32A | C26: 43293 | D26: Dugout2018_32A-JULY12 | E26: TIC | F26: 63.358
A27: =B27&C27 -> 32A43243 | B27: 32A | C27: 43243 | D27: Dugout2018_32A-MAY23 | E27: TIC | F27: 52.526
A28: =B28&C28 -> 32B43370 | B28: 32B | C28: 43370 | D28: Dugout2018_32B-SEPT27 | E28: TIC | F28: 55.543
A29: =B29&C29 -> 32B43221 | B29: 32B | C29: 43221 | D29: Dugout2018_32B-MAY1 | E29: TIC | F29: 40.772
A30: =B30&C30 -> 32B43243 | B30: 32B | C30: 43243 | D30: Dugout2018_32B-MAY23 | E30: TIC | F30: 52.508
A31: =B31&C31 -> 32B43293 | B31: 32B | C31: 43293 | D31: Dugout2018_32B-JULY12 | E31: TIC | F31: 50.303
A32: =B32&C32 -> 32C43237 | B32: 32C | C32: 43237 | D32: Dugout2018_32C-MAY17 | E32: TIC | F32: 43.126
A33: =B33&C33 -> 32C43221 | B33: 32C | C33: 43221 | D33: Dugout2018_32C-MAY1 | E33: TIC | F33: 29.199
A34: =B34&C34 -> 32C43370 | B34: 32C | C34: 43370 | D34: Dugout2018_32C-SEPT27 | E34: TIC | F34: 46.541
A35: =B35&C35 -> 32C43293 | B35: 32C | C35: 43293 | D35: Dugout2018_32C-JULY12 | E35: TIC | F35: 45.867
... A43: =B43&C43 -> 4C43369 | B43: 4C | C43: 43369 | D43: Dugout2018_4C-SEPT20 | E43: TIC | F43: 30.796
A44: =B44&C44 -> 4C24 Hr | B44: 4C | C44: 24 Hr | D44: Dugout2018_4C-24hr-JULY26 | E44: TIC | F44: 25.28
A45: =B45&C45 -> 4C43292 | B45: 4C | C45: 43292 | D45: Dugout2018_4C-JULY11 | E45: TIC | F45: 21.431
A46: =B46&C46 -> 4C43214 | B46: 4C | C46: 43214 | D46: Dugout2018_4C-APR24 | E46: TIC | F46: 31.409
A47: =B47&C47 -> 4C0 Hr | B47: 4C | C47: 0 Hr | D47: Dugout2018_4C-0h-JULY25 | E47: TIC | F47: 26.979
...

Sheet TOC
A1: Sorting | B1: SiteID | C1: Date | D1: Sample | E1: TOC/TIC | F1: PPM
A2: =B2&C2 -> 2343370 | B2: 23 | C2: 43370 | D2: Dugout2018_23-SEPT27 | E2: TOC | F2: 19.244
A3: =B3&C3 -> 2343321 | B3: 23 | C3: 43321 | D3: Dugout2018_23-AUG9 | E3: TOC | F3: 19.255
A4: =B4&C4 -> 2343237 | B4: 23 | C4: 43237 | D4: Dugout2018_23-MAY17 | E4: TOC | F4: 11.377
A5: =B5&C5 -> 2343293 | B5: 23 | C5: 43293 | D5: Dugout2018_23-JULY12 | E5: TOC | F5: 15.997
A6: =B6&C6 -> 2343262 | B6: 23 | C6: 43262 | D6: Dugout2018_23-JUNE11 | E6: TOC | F6: 11.091
A7: =B7&C7 -> 6843294 | B7: 68 | C7: 43294 | D7: Dugout2018_68-JULY13 | E7: TOC | F7: 25.507
A8: =B8&C8 -> 6843238 | B8: 68 | C8: 43238 | D8: Dugout2018_68-MAY18 | E8: TOC | F8: 20.657
A9: =B9&C9 -> 6843216 | B9: 68 | C9: 43216 | D9: Dugout2018_68-APR26 | E9: TOC | F9: 17.09
A10: =B10&C10 -> 14A43371 | B10: 14A | C10: 43371 | D10: Dugout2018_14A-SEPT28 | E10: TOC | F10: 53.38
A11: =B11&C11 -> 14A43238 | B11: 14A | C11: 43238 | D11: Dugout2018_14A-MAY18 | E11: TOC | F11: 38.182
A12: =B12&C12 -> 14A43294 | B12: 14A | C12: 43294 | D12: Dugout2018_14A-JULY13 | E12: TOC | F12: 45.595
A13: =B13&C13 -> 14A43216 | B13: 14A | C13: 43216 | D13: Dugout2018_14A-APR26 | E13: TOC | F13: 23.294
A14: =B14&C14 -> 14A0 Hr | B14: 14A | C14: 0 Hr | D14: Dugout2018_14A-0H-JUNE26 | E14: TOC | F14: 43.52
A15: =B15&C15 -> 14A12 Hr | B15: 14A | C15: 12 Hr | D15: Dugout2018_14A-12H-JUNE26 | E15: TOC | F15: 43.797
A16: =B16&C16 -> 14A24 Hr | B16: 14A | C16: 24 Hr | D16: Dugout2018_14A-24H-JUNE26 | E16: TOC | F16: 47.744
A17: =B17&C17 -> 14B43371 | B17: 14B | C17: 43371 | D17: Dugout2018_14B-SEPT28 | E17: TOC | F17: 29.123
A18: =B18&C18 -> 14B43238 | B18: 14B | C18: 43238 | D18: Dugout2018_14B-MAY18 | E18: TOC | F18: 24.814
A19: =B19&C19 -> 14B43294 | B19: 14B | C19: 43294 | D19: Dugout2018_14B-JULY13 | E19: TOC | F19: 26.508
A20: =B20&C20 -> 14B43216 | B20: 14B | C20: 43216 | D20: Dugout2018_14B-APR26 | E20: TOC | F20: 24.325
A21: =B21&C21 -> 230 Hr | B21: 23 | C21: 0 Hr | D21: Dugout2018_23-0h-JULY31 | E21: TOC | F21: 16.942
A22: =B22&C22 -> 2312 Hr | B22: 23 | C22: 12 Hr | D22: Dugout2018_23-12h-JULY31 | E22: TOC | F22: 17.04
A23: =B23&C23 -> 2324 Hr | B23: 23 | C23: 24 Hr | D23: Dugout2018_23-24h-AUG1 | E23: TOC | F23: 17.122
A24: =B24&C24 -> 32A43370 | B24: 32A | C24: 43370 | D24: Dugout2018_32A-SEPT27 | E24: TOC | F24: 38.127
A25: =B25&C25 -> 32A43221 | B25: 32A | C25: 43221 | D25: Dugout2018_32A-MAY1 | E25: TOC | F25: 26.023
A26: =B26&C26 -> 32A43293 | B26: 32A | C26: 43293 | D26: Dugout2018_32A-JULY12 | E26: TOC | F26: 28.143
A27: =B27&C27 -> 32A43243 | B27: 32A | C27: 43243 | D27: Dugout2018_32A-MAY23 | E27: TOC | F27: 29.976
A28: =B28&C28 -> 32B43370 | B28: 32B | C28: 43370 | D28: Dugout2018_32B-SEPT27 | E28: TOC | F28: 28.791
A29: =B29&C29 -> 32B43221 | B29: 32B | C29: 43221 | D29: Dugout2018_32B-MAY1 | E29: TOC | F29: 21.282
A30: =B30&C30 -> 32B43243 | B30: 32B | C30: 43243 | D30: Dugout2018_32B-MAY23 | E30: TOC | F30: 23.323
A31: =B31&C31 -> 32B43293 | B31: 32B | C31: 43293 | D31: Dugout2018_32B-JULY12 | E31: TOC | F31: 23.735
A32: =B32&C32 -> 32C43237 | B32: 32C | C32: 43237 | D32: Dugout2018_32C-MAY17 | E32: TOC | F32: 21.624
A33: =B33&C33 -> 32C43221 | B33: 32C | C33: 43221 | D33: Dugout2018_32C-MAY1 | E33: TOC | F33: 17
A34: =B34&C34 -> 32C43370 | B34: 32C | C34: 43370 | D34: Dugout2018_32C-SEPT27 | E34: TOC | F34: 31.373
A35: =B35&C35 -> 32C43293 | B35: 32C | C35: 43293 | D35: Dugout2018_32C-JULY12 | E35: TOC | F35: 24.526
... A43: =B43&C43 -> 4C43369 | B43: 4C | C43: 43369 | D43: Dugout2018_4C-SEPT20 | E43: TOC | F43: 16.736
A44: =B44&C44 -> 4C24 Hr | B44: 4C | C44: 24 Hr | D44: Dugout2018_4C 24 Hr-JULY26 | E44: TOC | F44: 17.533
A45: =B45&C45 -> 4C43292 | B45: 4C | C45: 43292 | D45: Dugout2018_4C-JULY11 | E45: TOC | F45: 15.794
A46: =B46&C46 -> 4C43214 | B46: 4C | C46: 43214 | D46: Dugout2018_4C-APR24 | E46: TOC | F46: 15.365
A47: =B47&C47 -> 4C0 Hr | B47: 4C | C47: 0 Hr | D47: Dugout2018_4C-0h-JULY25 | E47: TOC | F47: 17.148
...

Sheet GHG
