Workbook

Sheet Legend
A2: U1-3 | B2: Control
A3: U19-21 | B3: 1 mg Urea / L
A4: U16-18 | B4: 3 mg Urea / L
A5: U13-15 | B5: 10 mg Urea / L
A6: U10-12 | B6: 30 mg Urea / L
A7: U7-9 | B7: 100 mg Urea / L
A8: U4-6 | B8: 300 mg Urea / L

Sheet Mortalities
A2: Treatment Group | B2: 16-04-2019 | C2: 17-04-2019 | D2: 18-04-2019 | E2: 19-04-2019 | F2: AV (#) | G2: AV (%) | H2: Fish in Tank
A3: U1-CTR | B3: 0 | C3: 0 | D3: 0 | E3: 0 | F3: =AVERAGE(B3:E3) -> 0 | G3: =F3/H3*100 -> 0 | H3: 10
A4: U2-CTR | B4: 0 | C4: 0 | D4: 0 | E4: 0 | F4: =AVERAGE(B4:E4) -> 0 | G4: =F4/H4*100 -> 0 | H4: 10
A5: U3-CTR | B5: 0 | C5: 0 | D5: 0 | E5: 0 | F5: =AVERAGE(B5:E5) -> 0 | G5: =F5/H5*100 -> 0 | H5: 11
A6: U19-1 | B6: 0 | C6: 0 | D6: 0 | E6: 0 | F6: =AVERAGE(B6:E6) -> 0 | G6: =F6/H6*100 -> 0 | H6: 10
A7: U20-1 | B7: 0 | C7: 1 | D7: 2 | E7: 0 | F7: =AVERAGE(B7:E7) -> 0.75 | G7: =F7/H7*100 -> 8.3333333 | H7: 9
A8: U21-1 | B8: 0 | C8: 0 | D8: 0 | E8: 0 | F8: =AVERAGE(B8:E8) -> 0 | G8: =F8/H8*100 -> 0 | H8: 10
A9: U16-3 | B9: 0 | C9: 0 | D9: 0 | E9: 0 | F9: =AVERAGE(B9:E9) -> 0 | G9: =F9/H9*100 -> 0 | H9: 10
A10: U17-3 | B10: 0 | C10: 0 | D10: 0 | E10: 0 | F10: =AVERAGE(B10:E10) -> 0 | G10: =F10/H10*100 -> 0 | H10: 10
A11: U18-3 | B11: 0 | C11: 0 | D11: 0 | E11: 0 | F11: =AVERAGE(B11:E11) -> 0 | G11: =F11/H11*100 -> 0 | H11: 10
A12: U13-C10 | B12: 0 | C12: 0 | D12: 0 | E12: 0 | F12: =AVERAGE(B12:E12) -> 0 | G12: =F12/H12*100 -> 0 | H12: 10
A13: U14-C10 | B13: 0 | C13: 0 | D13: 0 | E13: 0 | F13: =AVERAGE(B13:E13) -> 0 | G13: =F13/H13*100 -> 0 | H13: 9
A14: U15-C10 | B14: 0 | C14: 0 | D14: 0 | E14: 0 | F14: =AVERAGE(B14:E14) -> 0 | G14: =F14/H14*100 -> 0 | H14: 10
... A23: U6-300 | B23: 0 | C23: 0 | D23: 0 | E23: 0 | F23: =AVERAGE(B23:E23) -> 0 | G23: =F23/H23*100 -> 0 | H23: 9

Sheet Water Quality
B2: 16-04-2019 | G2: 17-04-2019 | L2: 19-04-2019
A3: Treatment Group | B3: DO [%] | C3: pH | D3: Temp [C] | E3: Conuctivity | F3: Ammonia [mg/L] | G3: DO [%] | H3: pH | I3: Temp [C] | J3: Conuctivity | K3: Ammonia [mg/L] | L3: DO [%] | M3: pH | N3: Temp [C] | O3: Conuctivity | P3: Ammonia [mg/L]
A4: U1-CTR | L4: 105 | M4: 7.8 | N4: 12.8 | O4: 450 | P4: 0.25
A5: U2-CTR | G5: 8 | H5: 7.7 | I5: 12.2 | J5: 447
A6: U3-CTR | B6: 87 | C6: 7.9 | D6: 12.1 | E6: 479 | F6: 0.25
A7: U19-1 | L7: 97 | M7: 7.7 | N7: 12.9 | O7: 441 | P7: 0
A8: U20-1 | B8: 82.5 | C8: 7.6 | D8: 12.1 | E8: 457 | F8: 0
A9: U21-1 | G9: 67 | H9: 7.5 | I9: 12.1 | J9: 430
A10: U16-3 | B10: 81 | C10: 7.5 | D10: 11.8 | E10: 467 | F10: 0.5 | G10: 89 | H10: 7.5 | I10: 11.8 | J10: 446
A11: U17-3 | L11: 87 | M11: 7.6 | N11: 13.1 | O11: 442 | P11: 0
A12: U18-3
A13: U13-C10 | L13: 89 | M13: 7.6 | N13: 12.6 | O13: 446 | P13: 0.25
A14: U14-C10 | G14: 84 | H14: 7.6 | I14: 12.3 | J14: 447
A15: U15-C10 | B15: 87 | C15: 7.6 | D15: 12 | E15: 468 | F15: 0.5
A16: U10-30
A17: U11-30 | B17: 70 | C17: 7.7 | D17: 12 | E17: 458 | F17: 0.25 | G17: 89 | H17: 7.6 | I17: 11.9 | J17: 444
A18: U12-30 | L18: 93 | M18: 7.7 | N18: 12.2 | O18: 439 | P18: 0.5
A19: U7-100 | L19: 95 | M19: 7.7 | N19: 12.1 | O19: 440 | P19: 0.25
A20: U8-100 | G20: 85 | H20: 7.6 | I20: 12 | J20: 446
A21: U9-100 | B21: 69 | C21: 7.4 | D21: 12.3 | E21: 464 | F21: 0
A22: U4-300 | G22: 90 | H22: 7.6 | I22: 11.8 | J22: 442
A23: U5-300 | B23: 88 | C23: 7.5 | D23: 11.9 | E23: 464 | F23: 0.5
A24: U6-300 | L24: 102 | M24: 7.7 | N24: 12 | O24: 441 | P24: 0.25

Sheet Termination
G2: Weight [g] | I2: Length [mm] | L2: Weight [g] | N2: Length [mm]
A3: Treatment Group | B3: Sample ID | C3: Weight [g] | D3: Length [mm] | E3: Comments (Replicate) | F3: Comments (Tank) | G3: AV | H3: SD | I3: AV | J3: SD
A4: U1-CTR | B4: U1-1 | C4: 1.6 | D4: 58 | G4: =AVERAGE(C4:C13) -> 1.701 | H4: =STDEV(C4:C13) -> 0.15673403 | I4: =AVERAGE(D4:D13) -> 58.1 | J4: =STDEV(D4:D13) -> 1.8529256 | L4: =AVERAGE(G4,G14,G24) -> 1.7106667 | M4: =STDEV(G4,G14,G24) -> 0.11480563 | N4: =AVERAGE(I4,I14,I24) -> 57.6 | O4: =STDEV(I4,I14,I24) -> 0.78102497
A5: U1-CTR | B5: U1-2 | C5: 1.74 | D5: 57
A6: U1-CTR | B6: U1-3 | C6: 1.85 | D6: 60
A7: U1-CTR | B7: U1-4 | C7: 1.79 | D7: 60
A8: U1-CTR | B8: U1-5 | C8: 1.73 | D8: 59
A9: U1-CTR | B9: U1-6 | C9: 1.83 | D9: 60
A10: U1-CTR | B10: U1-7 | C10: 1.57 | D10: 57
A11: U1-CTR | B11: U1-8 | C11: 1.34 | D11: 54
A12: U1-CTR | B12: U1-9 | C12: 1.81 | D12: 58
A13: U1-CTR | B13: U1-10 | C13: 1.75 | D13: 58
A14: U2-CTR | B14: U2-1 | C14: 1.9 | D14: 60 | G14: =AVERAGE(C14:C23) -> 1.601 | H14: =STDEV(C14:C23) -> 0.33214622 | I14: =AVERAGE(D14:D23) -> 56.7 | J14: =STDEV(D14:D23) -> 3.4976182
A15: U2-CTR | B15: U2-2 | C15: 1.79 | D15: 59
A16: U2-CTR | B16: U2-3 | C16: 2.01 | D16: 62
A17: U2-CTR | B17: U2-4 | C17: 1.21 | D17: 53
A18: U2-CTR | B18: U2-5 | C18: 1.25 | D18: 54
A19: U2-CTR | B19: U2-6 | C19: 1.98 | D19: 60
A20: U2-CTR | B20: U2-7 | C20: 1.42 | D20: 55
A21: U2-CTR | B21: U2-8 | C21: 1.45 | D21: 54
A22: U2-CTR | B22: U2-9 | C22: 1.18 | D22: 52
A23: U2-CTR | B23: U2-10 | C23: 1.82 | D23: 58
A24: U3-CTR | B24: U3-1 | C24: 1.86 | D24: 58 | G24: =AVERAGE(C24:C34) -> 1.83 | H24: =STDEV(C24:C34) -> 0.23845335 | I24: =AVERAGE(D24:D34) -> 58 | J24: =STDEV(D24:D34) -> 2.2803509
A25: U3-CTR | B25: U3-2 | C25: 2.22 | D25: 62
A26: U3-CTR | B26: U3-3 | C26: 1.63 | D26: 56
A27: U3-CTR | B27: U3-4 | C27: 2.2 | D27: 62
A28: U3-CTR | B28: U3-5 | C28: 1.97 | D28: 59
A29: U3-CTR | B29: U3-6 | C29: 1.68 | D29: 57
A30: U3-CTR | B30: U3-7 | C30: 1.67 | D30: 58
A31: U3-CTR | B31: U3-8 | C31: 1.97 | D31: 57
A32: U3-CTR | B32: U3-9 | C32: 1.56 | D32: 55
A33: U3-CTR | B33: U3-10 | C33: 1.55 | D33: 56
A34: U3-CTR | B34: U3-11 | C34: 1.82 | D34: 58
A35: U19-1 | B35: U19-1 | C35: 1.84 | D35: 53 | F35: Two fish lost buycancy but righted themselves up again when prodded | G35: =AVERAGE(C35:C44) -> 1.783 | H35: =STDEV(C35:C44) -> 0.3638391 | I35: =AVERAGE(D35:D44) -> 53.2 | J35: =STDEV(D35:D44) -> 2.9363621 | L35: =AVERAGE(G35,G45,G55) -> 1.7623333 | M35: =STDEV(G35,G45,G55) -> 0.060698709 | N35: =AVERAGE(I35,I45,I55) -> 53.9 | O35: =STDEV(I35,I45,I55) -> 1.3892444
A36: U19-1 | B36: U19-2 | C36: 2.28 | D36: 57
A37: U19-1 | B37: U19-3 | C37: 1.26 | D37: 49 | E37: Very small and skinny appearance
A38: U19-1 | B38: U19-4 | C38: 1.87 | D38: 51
A39: U19-1 | B39: U19-5 | C39: 1.56 | D39: 55
A40: U19-1 | B40: U19-6 | C40: 1.39 | D40: 49
A41: U19-1 | B41: U19-7 | C41: 1.59 | D41: 54
...

Sheet Summary
B1: Mortality | D1: Weight | F1: Length
A2: Treatment | B2: Avergae Mortality | C2: SD | D2: Avergae weight (g) | E2: SD | F2: Avergae Length (mm) | G2: SD
A3: CTR | B3: =AVERAGE(Mortalities!G3:G5) -> 0 | C3: =STDEV(Mortalities!G3:G5) -> 0 | D3: =Termination!L4 -> 1.7106667 | E3: =Termination!M4 -> 0.11480563 | F3: =Termination!N4 -> 57.6 | G3: =Termination!O4 -> 0.78102497
A4: 1 | B4: =AVERAGE(Mortalities!G6:G8) -> 2.7777778 | C4: =STDEV(Mortalities!G6:G8) -> 4.8112522 | D4: =Termination!L35 -> 1.7623333 | E4: =Termination!M35 -> 0.060698709 | F4: =Termination!N35 -> 53.9 | G4: =Termination!O35 -> 1.3892444
A5: 3 | B5: =AVERAGE(Mortalities!G9:G11) -> 0 | C5: =STDEV(Mortalities!G9:G11) -> 0 | D5: =Termination!L65 -> 1.7676667 | E5: =Termination!M65 -> 0.11849191 | F5: =Termination!N65 -> 57.433333 | G5: =Termination!O65 -> 0.83864971
A6: 10 | B6: =AVERAGE(Mortalities!G12:G14) -> 0 | C6: =STDEV(Mortalities!G12:G14) -> 0 | D6: =Termination!L95 -> 1.6697037 | E6: =Termination!M95 -> 0.037509066 | F6: =Termination!N95 -> 56.577778 | G6: =Termination!O95 -> 0.88777708
A7: 30 | B7: =AVERAGE(Mortalities!G15:G17) -> 0 | C7: =STDEV(Mortalities!G15:G17) -> 0 | D7: =Termination!L125 -> 1.7276667 | E7: =Termination!M125 -> 0.14101891 | F7: =Termination!N125 -> 55.314815 | G7: =Termination!O125 -> 2.1841837
A8: 100 | B8: =AVERAGE(Mortalities!G18:G20) -> 0.83333333 | C8: =STDEV(Mortalities!G18:G20) -> 1.4433757 | D8: =Termination!L155 -> 1.565 | E8: =Termination!M155 -> 0.10404326 | F8: =Termination!N155 -> 54.9 | G8: =Termination!O155 -> 0.52915026
A9: 300 | B9: =AVERAGE(Mortalities!G21:G23) -> 3.3333333 | C9: =STDEV(Mortalities!G21:G23) -> 5.7735027 | D9: =Termination!L185 -> 1.7022222 | E9: =Termination!M185 -> 0.072273486 | F9: =Termination!N185 -> 55.356481 | G9: =Termination!O185 -> 2.4431947
